â”€â”€â”€â”€â”€â”€â”€â”€â”€â”€â”€â”€â”€â”€â”€â”€â”€â”€â”€â”€â”€â”€â”€â”€â”€â”€â”€â”€â”€â”€â”€â”€ Installing Streamlit â”€â”€â”€â”€â”€â”€â”€â”€â”€â”€â”€â”€â”€â”€â”€â”€â”€â”€â”€â”€â”€â”€â”€â”€â”€â”€â”€â”€â”€â”€â”€â”€â”€â”€


Using uv pip install.

Using Python 3.13.6 environment at /home/adminuser/venv

Resolved [2025-08-30 09:24:50.654250] 37 packages[2025-08-30 09:24:50.654550]  [2025-08-30 09:24:50.654855] in 461ms[2025-08-30 09:24:50.655139] 

Prepared 37 packages in 1.56s

Installed 37 packages in 70ms

 + altair==5.5.0

 + attrs==25.3.0

 + blinker==1.9.0

 + cachetools==6.2.0

 + certifi==2025.8.3

 + charset-normalizer==3.4.3[2025-08-30 09:24:52.286002] 

 + click==8.2.1

 + gitdb==4.0.12

 + gitpython==3.1.45

 + idna==3.10

 + jinja2==3.1.6

 + jsonschema==4.25.1

 + [2025-08-30 09:24:52.286215] jsonschema-specifications==2025.4.1

 + markupsafe==3.0.2

 + narwhals==2.2.0

 + numpy==2.3.2

 + packaging==25.0

 + pandas[2025-08-30 09:24:52.286397] ==2.3.2

 + pillow==11.3.0

 + protobuf==6.32.0

 + pyarrow==21.0.0

 + pydeck==0.9.1

 + python-dateutil==2.9.0.post0

 [2025-08-30 09:24:52.286498] + pytz==2025.2

 + referencing==0.36.2

 + requests==2.32.5

 + rpds-py==0.27.1[2025-08-30 09:24:52.286614] 

 + six==1.17.0

 + smmap==5.0.2

 + streamlit==1.49.1

 + tenacity==9.1.2

 + toml==0.10.2[2025-08-30 09:24:52.286771] 

 + tornado==6.5.2

 + typing-extensions==4.15.0

 + tzdata[2025-08-30 09:24:52.286903] ==2025.2

 + urllib3==2.5.0

 + watchdog==6.0.0


â”€â”€â”€â”€â”€â”€â”€â”€â”€â”€â”€â”€â”€â”€â”€â”€â”€â”€â”€â”€â”€â”€â”€â”€â”€â”€â”€â”€â”€â”€â”€â”€â”€â”€â”€â”€â”€â”€â”€â”€â”€â”€â”€â”€â”€â”€â”€â”€â”€â”€â”€â”€â”€â”€â”€â”€â”€â”€â”€â”€â”€â”€â”€â”€â”€â”€â”€â”€â”€â”€â”€â”€â”€â”€â”€â”€â”€â”€â”€â”€â”€â”€â”€â”€â”€â”€â”€â”€


[09:24:52] ðŸ“¦ Processed dependencies!

cat: /mount/admin/install_path: No such file or directory




2025-08-30 09:24:59.909 Uncaught app execution

Traceback (most recent call last):

  File "/home/adminuser/venv/lib/python3.13/site-packages/streamlit/runtime/scriptrunner/exec_code.py", line 128, in exec_func_with_error_handling

    result = func()

  File "/home/adminuser/venv/lib/python3.13/site-packages/streamlit/runtime/scriptrunner/script_runner.py", line 669, in code_to_exec

    exec(code, module.__dict__)  # noqa: S102

    ~~~~^^^^^^^^^^^^^^^^^^^^^^^

  File "/mount/src/automatic-job-apply-agent/job_app.py", line 2, in <module>

    import google.generativeai as genai

ModuleNotFoundError: No module named 'google.generativeai'

2025-08-30 09:25:34.294 Uncaught app execution

Traceback (most recent call last):

  File "/home/adminuser/venv/lib/python3.13/site-packages/streamlit/runtime/scriptrunner/exec_code.py", line 128, in exec_func_with_error_handling

    result = func()

  File "/home/adminuser/venv/lib/python3.13/site-packages/streamlit/runtime/scriptrunner/script_runner.py", line 669, in code_to_exec

    exec(code, module.__dict__)  # noqa: S102

    ~~~~^^^^^^^^^^^^^^^^^^^^^^^

  File "/mount/src/automatic-job-apply-agent/job_app.py", line 2, in <module>

    import google.generativeai as genai

ModuleNotFoundError: No module named 'google.generativeai'

2025-08-30 09:25:39.795 Uncaught app execution

Traceback (most recent call last):

  File "/home/adminuser/venv/lib/python3.13/site-packages/streamlit/runtime/scriptrunner/exec_code.py", line 128, in exec_func_with_error_handling

    result = func()

  File "/home/adminuser/venv/lib/python3.13/site-packages/streamlit/runtime/scriptrunner/script_runner.py", line 669, in code_to_exec

    exec(code, module.__dict__)  # noqa: S102

    ~~~~^^^^^^^^^^^^^^^^^^^^^^^

  File "/mount/src/automatic-job-apply-agent/job_app.py", line 2, in <module>

    import google.generativeai as genai

ModuleNotFoundError: No module named 'google.generativeai'

main
kishan195-sudo/automatic-job-apply-agent/main/job_app.py
